2025-04-25 13:20:57,775 INFO    Thread-10 (_run_job):34956 [wandb_setup.py:_flush():68] Current SDK version is 0.19.2
2025-04-25 13:20:57,775 INFO    Thread-10 (_run_job):34956 [wandb_setup.py:_flush():68] Configure stats pid to 34956
2025-04-25 13:20:57,776 INFO    Thread-10 (_run_job):34956 [wandb_setup.py:_flush():68] Loading settings from C:\Users\alonl\.config\wandb\settings
2025-04-25 13:20:57,776 INFO    Thread-10 (_run_job):34956 [wandb_setup.py:_flush():68] Loading settings from C:\Users\alonl\PycharmProjects\GI_Machine_Learning_Project_BIU\Wrist_Original_Architecture\wandb\settings
2025-04-25 13:20:57,776 INFO    Thread-10 (_run_job):34956 [wandb_setup.py:_flush():68] Loading settings from environment variables
2025-04-25 13:20:57,777 INFO    Thread-10 (_run_job):34956 [wandb_init.py:_log_setup():523] Logging user logs to C:\Users\alonl\PycharmProjects\GI_Machine_Learning_Project_BIU\Wrist_Original_Architecture\wandb\run-20250425_132057-jxv2bm6s\logs\debug.log
2025-04-25 13:20:57,778 INFO    Thread-10 (_run_job):34956 [wandb_init.py:_log_setup():524] Logging internal logs to C:\Users\alonl\PycharmProjects\GI_Machine_Learning_Project_BIU\Wrist_Original_Architecture\wandb\run-20250425_132057-jxv2bm6s\logs\debug-internal.log
2025-04-25 13:20:57,778 INFO    Thread-10 (_run_job):34956 [wandb_init.py:init():641] calling init triggers
2025-04-25 13:20:57,778 INFO    Thread-10 (_run_job):34956 [wandb_init.py:init():647] wandb.init called with sweep_config: {'batch_size': 16, 'epoch': 10, 'lr': 0.0002, 'sampling_rate': 0.5, 'shape': '32_64'}
config: {}
2025-04-25 13:20:57,778 INFO    Thread-10 (_run_job):34956 [wandb_init.py:init():674] starting backend
2025-04-25 13:20:58,018 INFO    Thread-10 (_run_job):34956 [wandb_init.py:init():678] sending inform_init request
2025-04-25 13:20:58,088 INFO    Thread-10 (_run_job):34956 [backend.py:_multiprocessing_setup():104] multiprocessing start_methods=spawn, using: spawn
2025-04-25 13:20:58,089 INFO    Thread-10 (_run_job):34956 [wandb_init.py:init():693] backend started and connected
2025-04-25 13:20:58,090 INFO    Thread-10 (_run_job):34956 [wandb_run.py:_config_callback():1283] config_cb None None {'batch_size': 16, 'epoch': 10, 'lr': 0.0002, 'sampling_rate': 0.5, 'shape': '32_64'}
2025-04-25 13:20:58,091 INFO    Thread-10 (_run_job):34956 [wandb_init.py:init():786] updated telemetry
2025-04-25 13:20:58,133 INFO    Thread-10 (_run_job):34956 [wandb_init.py:init():818] communicating run to backend with 90.0 second timeout
2025-04-25 13:20:58,644 INFO    Thread-10 (_run_job):34956 [wandb_init.py:init():868] starting run threads in backend
2025-04-25 13:20:58,738 INFO    Thread-10 (_run_job):34956 [wandb_run.py:_console_start():2415] atexit reg
2025-04-25 13:20:58,738 INFO    Thread-10 (_run_job):34956 [wandb_run.py:_redirect():2265] redirect: wrap_raw
2025-04-25 13:20:58,738 INFO    Thread-10 (_run_job):34956 [wandb_run.py:_redirect():2330] Wrapping output streams.
2025-04-25 13:20:58,738 INFO    Thread-10 (_run_job):34956 [wandb_run.py:_redirect():2355] Redirects installed.
2025-04-25 13:20:58,742 INFO    Thread-10 (_run_job):34956 [wandb_init.py:init():910] run started, returning control to user process
2025-04-25 15:22:20,502 INFO    Thread-9 (_heartbeat):34956 [retry.py:__call__():172] Retry attempt failed:
Traceback (most recent call last):
  File "C:\Users\alonl\AppData\Local\Programs\Python\Python312\Lib\site-packages\urllib3\connection.py", line 198, in _new_conn
    sock = connection.create_connection(
           ^^^^^^^^^^^^^^^^^^^^^^^^^^^^^
  File "C:\Users\alonl\AppData\Local\Programs\Python\Python312\Lib\site-packages\urllib3\util\connection.py", line 60, in create_connection
    for res in socket.getaddrinfo(host, port, family, socket.SOCK_STREAM):
               ^^^^^^^^^^^^^^^^^^^^^^^^^^^^^^^^^^^^^^^^^^^^^^^^^^^^^^^^^^
  File "C:\Users\alonl\AppData\Local\Programs\Python\Python312\Lib\socket.py", line 976, in getaddrinfo
    for res in _socket.getaddrinfo(host, port, family, type, proto, flags):
               ^^^^^^^^^^^^^^^^^^^^^^^^^^^^^^^^^^^^^^^^^^^^^^^^^^^^^^^^^^^
socket.gaierror: [Errno 11001] getaddrinfo failed

The above exception was the direct cause of the following exception:

Traceback (most recent call last):
  File "C:\Users\alonl\AppData\Local\Programs\Python\Python312\Lib\site-packages\urllib3\connectionpool.py", line 787, in urlopen
    response = self._make_request(
               ^^^^^^^^^^^^^^^^^^^
  File "C:\Users\alonl\AppData\Local\Programs\Python\Python312\Lib\site-packages\urllib3\connectionpool.py", line 488, in _make_request
    raise new_e
  File "C:\Users\alonl\AppData\Local\Programs\Python\Python312\Lib\site-packages\urllib3\connectionpool.py", line 464, in _make_request
    self._validate_conn(conn)
  File "C:\Users\alonl\AppData\Local\Programs\Python\Python312\Lib\site-packages\urllib3\connectionpool.py", line 1093, in _validate_conn
    conn.connect()
  File "C:\Users\alonl\AppData\Local\Programs\Python\Python312\Lib\site-packages\urllib3\connection.py", line 704, in connect
    self.sock = sock = self._new_conn()
                       ^^^^^^^^^^^^^^^^
  File "C:\Users\alonl\AppData\Local\Programs\Python\Python312\Lib\site-packages\urllib3\connection.py", line 205, in _new_conn
    raise NameResolutionError(self.host, self, e) from e
urllib3.exceptions.NameResolutionError: <urllib3.connection.HTTPSConnection object at 0x0000021313CDFE00>: Failed to resolve 'api.wandb.ai' ([Errno 11001] getaddrinfo failed)

The above exception was the direct cause of the following exception:

Traceback (most recent call last):
  File "C:\Users\alonl\AppData\Local\Programs\Python\Python312\Lib\site-packages\requests\adapters.py", line 667, in send
    resp = conn.urlopen(
           ^^^^^^^^^^^^^
  File "C:\Users\alonl\AppData\Local\Programs\Python\Python312\Lib\site-packages\urllib3\connectionpool.py", line 841, in urlopen
    retries = retries.increment(
              ^^^^^^^^^^^^^^^^^^
  File "C:\Users\alonl\AppData\Local\Programs\Python\Python312\Lib\site-packages\urllib3\util\retry.py", line 519, in increment
    raise MaxRetryError(_pool, url, reason) from reason  # type: ignore[arg-type]
    ^^^^^^^^^^^^^^^^^^^^^^^^^^^^^^^^^^^^^^^^^^^^^^^^^^^
urllib3.exceptions.MaxRetryError: HTTPSConnectionPool(host='api.wandb.ai', port=443): Max retries exceeded with url: /graphql (Caused by NameResolutionError("<urllib3.connection.HTTPSConnection object at 0x0000021313CDFE00>: Failed to resolve 'api.wandb.ai' ([Errno 11001] getaddrinfo failed)"))

During handling of the above exception, another exception occurred:

Traceback (most recent call last):
  File "C:\Users\alonl\AppData\Local\Programs\Python\Python312\Lib\site-packages\wandb\sdk\lib\retry.py", line 131, in __call__
    result = self._call_fn(*args, **kwargs)
             ^^^^^^^^^^^^^^^^^^^^^^^^^^^^^^
  File "C:\Users\alonl\AppData\Local\Programs\Python\Python312\Lib\site-packages\wandb\sdk\internal\internal_api.py", line 393, in execute
    return self.client.execute(*args, **kwargs)  # type: ignore
           ^^^^^^^^^^^^^^^^^^^^^^^^^^^^^^^^^^^^
  File "C:\Users\alonl\AppData\Local\Programs\Python\Python312\Lib\site-packages\wandb\vendor\gql-0.2.0\wandb_gql\client.py", line 52, in execute
    result = self._get_result(document, *args, **kwargs)
             ^^^^^^^^^^^^^^^^^^^^^^^^^^^^^^^^^^^^^^^^^^^
  File "C:\Users\alonl\AppData\Local\Programs\Python\Python312\Lib\site-packages\wandb\vendor\gql-0.2.0\wandb_gql\client.py", line 60, in _get_result
    return self.transport.execute(document, *args, **kwargs)
           ^^^^^^^^^^^^^^^^^^^^^^^^^^^^^^^^^^^^^^^^^^^^^^^^^
  File "C:\Users\alonl\AppData\Local\Programs\Python\Python312\Lib\site-packages\wandb\sdk\lib\gql_request.py", line 58, in execute
    request = self.session.post(self.url, **post_args)
              ^^^^^^^^^^^^^^^^^^^^^^^^^^^^^^^^^^^^^^^^
  File "C:\Users\alonl\AppData\Local\Programs\Python\Python312\Lib\site-packages\requests\sessions.py", line 637, in post
    return self.request("POST", url, data=data, json=json, **kwargs)
           ^^^^^^^^^^^^^^^^^^^^^^^^^^^^^^^^^^^^^^^^^^^^^^^^^^^^^^^^^
  File "C:\Users\alonl\AppData\Local\Programs\Python\Python312\Lib\site-packages\requests\sessions.py", line 589, in request
    resp = self.send(prep, **send_kwargs)
           ^^^^^^^^^^^^^^^^^^^^^^^^^^^^^^
  File "C:\Users\alonl\AppData\Local\Programs\Python\Python312\Lib\site-packages\requests\sessions.py", line 703, in send
    r = adapter.send(request, **kwargs)
        ^^^^^^^^^^^^^^^^^^^^^^^^^^^^^^^
  File "C:\Users\alonl\AppData\Local\Programs\Python\Python312\Lib\site-packages\requests\adapters.py", line 700, in send
    raise ConnectionError(e, request=request)
requests.exceptions.ConnectionError: HTTPSConnectionPool(host='api.wandb.ai', port=443): Max retries exceeded with url: /graphql (Caused by NameResolutionError("<urllib3.connection.HTTPSConnection object at 0x0000021313CDFE00>: Failed to resolve 'api.wandb.ai' ([Errno 11001] getaddrinfo failed)"))
2025-04-25 17:15:46,468 INFO    Thread-10 (_run_job):34956 [wandb_run.py:_finish():2140] finishing run barilan/GI_Machine_Learning_Project/jxv2bm6s
2025-04-25 17:15:46,485 INFO    Thread-10 (_run_job):34956 [wandb_run.py:_atexit_cleanup():2380] got exitcode: 0
2025-04-25 17:15:46,489 INFO    Thread-10 (_run_job):34956 [wandb_run.py:_restore():2362] restore
2025-04-25 17:15:46,492 INFO    Thread-10 (_run_job):34956 [wandb_run.py:_restore():2368] restore done
2025-04-25 17:15:48,773 INFO    Thread-10 (_run_job):34956 [wandb_run.py:_footer_history_summary_info():3984] rendering history
2025-04-25 17:15:48,775 INFO    Thread-10 (_run_job):34956 [wandb_run.py:_footer_history_summary_info():4016] rendering summary
2025-04-25 17:15:48,894 INFO    Thread-10 (_run_job):34956 [wandb_run.py:_footer_sync_info():3945] logging synced files
